<?xml version="1.0" encoding="UTF-8"?>
<testsuites>
	<testsuite errors="0" failures="10" file="tests.py" name="tests.PostTestCase-20200420113333" skipped="0" tests="12" time="0.078" timestamp="2020-04-20T11:33:33">
		<testcase classname="tests.PostTestCase" file="module4\tests.py" line="114" name="test_task1_tag_model_exists" time="0.004" timestamp="2020-04-20T11:33:33">
			<system-out>
<![CDATA['Name' object has no attribute 's'
]]>			</system-out>
			<system-err>
<![CDATA[]]>			</system-err>
		</testcase>
		<testcase classname="tests.PostTestCase" file="module4\tests.py" line="132" name="test_task3_str_exists" time="0.006" timestamp="2020-04-20T11:33:33">
			<system-out>
<![CDATA['Name' object has no attribute 's'
]]>			</system-out>
			<system-err>
<![CDATA[]]>			</system-err>
		</testcase>
		<testcase classname="tests.PostTestCase" file="module4\tests.py" line="246" name="test_task10_uncomment_templates" time="0.014" timestamp="2020-04-20T11:33:33">
			<failure message="There is still a `{% comment %}` tag in `mainapp/templates/mainapp/snippet_post_list.html`" type="AssertionError">
<![CDATA[Traceback (most recent call last):
  File "C:\Users\arkadiusz.trzcinski\Documents\Projects\Django\python-django-models-authentication\module4\tests.py", line 255, in test_task10_uncomment_templates
    self.assertTrue(not comment_found, msg="There is still a `{% comment %}` tag in `" + filename + "`")
  File "C:\Users\arkadiusz.trzcinski\Documents\Projects\Django\python-django-models-authentication\support\SimplerTestCase.py", line 12, in assertTrue
    self.fail(msg or (str(expr) + "is not True"))
AssertionError: There is still a `{% comment %}` tag in `mainapp/templates/mainapp/snippet_post_list.html`
]]>			</failure>
			<system-out>
<![CDATA[]]>			</system-out>
			<system-err>
<![CDATA[]]>			</system-err>
		</testcase>
		<testcase classname="tests.PostTestCase" file="module4\tests.py" line="258" name="test_task11_admin_register_tag" time="0.006" timestamp="2020-04-20T11:33:33">
			<failure message="Did you import `Tag`?" type="AssertionError">
<![CDATA[Traceback (most recent call last):
  File "C:\Users\arkadiusz.trzcinski\Documents\Projects\Django\python-django-models-authentication\module4\tests.py", line 279, in test_task11_admin_register_tag
    self.assertTrue(import_Tag_found, msg="Did you import `Tag`?")
  File "C:\Users\arkadiusz.trzcinski\Documents\Projects\Django\python-django-models-authentication\support\SimplerTestCase.py", line 12, in assertTrue
    self.fail(msg or (str(expr) + "is not True"))
AssertionError: Did you import `Tag`?
]]>			</failure>
			<system-out>
<![CDATA[]]>			</system-out>
			<system-err>
<![CDATA[]]>			</system-err>
		</testcase>
		<testcase classname="tests.PostTestCase" file="module4\tests.py" line="282" name="test_task12_make_migrations" time="0.007" timestamp="2020-04-20T11:33:33">
			<failure message="Did you use `manage.py makemigrations` to create the `Tag` migrations file? Don't forget to `add` it to the git repo." type="AssertionError">
<![CDATA[Traceback (most recent call last):
  File "C:\Users\arkadiusz.trzcinski\Documents\Projects\Django\python-django-models-authentication\module4\tests.py", line 285, in test_task12_make_migrations
    self.assertTrue(self.check_migration('mainapp/migrations/', 'Tag'), msg=msg)
  File "C:\Users\arkadiusz.trzcinski\Documents\Projects\Django\python-django-models-authentication\support\SimplerTestCase.py", line 12, in assertTrue
    self.fail(msg or (str(expr) + "is not True"))
AssertionError: Did you use `manage.py makemigrations` to create the `Tag` migrations file? Don't forget to `add` it to the git repo.
]]>			</failure>
			<system-out>
<![CDATA[]]>			</system-out>
			<system-err>
<![CDATA[]]>			</system-err>
		</testcase>
		<testcase classname="tests.PostTestCase" file="module4\tests.py" line="125" name="test_task2_clean_method_exists" time="0.005" timestamp="2020-04-20T11:33:33">
			<failure message="Did you assign to `self.name` in the `clean` method?" type="AssertionError">
<![CDATA[Traceback (most recent call last):
  File "C:\Users\arkadiusz.trzcinski\Documents\Projects\Django\python-django-models-authentication\module4\tests.py", line 130, in test_task2_clean_method_exists
    self.assertTrue(self.clean_assign_found, msg="Did you assign to `self.name` in the `clean` method?")
  File "C:\Users\arkadiusz.trzcinski\Documents\Projects\Django\python-django-models-authentication\support\SimplerTestCase.py", line 12, in assertTrue
    self.fail(msg or (str(expr) + "is not True"))
AssertionError: Did you assign to `self.name` in the `clean` method?
]]>			</failure>
			<system-out>
<![CDATA['Name' object has no attribute 's'
]]>			</system-out>
			<system-err>
<![CDATA[]]>			</system-err>
		</testcase>
		<testcase classname="tests.PostTestCase" file="module4\tests.py" line="136" name="test_task4_many_to_many_exists" time="0.006" timestamp="2020-04-20T11:33:33">
			<failure message="Did you set `tags` equal to the `ManyToManyField`?" type="AssertionError">
<![CDATA[Traceback (most recent call last):
  File "C:\Users\arkadiusz.trzcinski\Documents\Projects\Django\python-django-models-authentication\module4\tests.py", line 139, in test_task4_many_to_many_exists
    self.assertTrue(self.tag_many_to_many_found, msg="Did you set `tags` equal to the `ManyToManyField`?")
  File "C:\Users\arkadiusz.trzcinski\Documents\Projects\Django\python-django-models-authentication\support\SimplerTestCase.py", line 12, in assertTrue
    self.fail(msg or (str(expr) + "is not True"))
AssertionError: Did you set `tags` equal to the `ManyToManyField`?
]]>			</failure>
			<system-out>
<![CDATA['Name' object has no attribute 's'
]]>			</system-out>
			<system-err>
<![CDATA[]]>			</system-err>
		</testcase>
		<testcase classname="tests.PostTestCase" file="module4\tests.py" line="192" name="test_task5_tag_view" time="0.004" timestamp="2020-04-20T11:33:33">
			<failure message="Did you return the result of the `render` function?" type="AssertionError">
<![CDATA[Traceback (most recent call last):
  File "C:\Users\arkadiusz.trzcinski\Documents\Projects\Django\python-django-models-authentication\module4\tests.py", line 196, in test_task5_tag_view
    self.assertTrue(self.tag_view_return_params_found, msg="Did you return the result of the `render` function?")
  File "C:\Users\arkadiusz.trzcinski\Documents\Projects\Django\python-django-models-authentication\support\SimplerTestCase.py", line 12, in assertTrue
    self.fail(msg or (str(expr) + "is not True"))
AssertionError: Did you return the result of the `render` function?
]]>			</failure>
			<system-out>
<![CDATA['Name' object has no attribute 'value'
]]>			</system-out>
			<system-err>
<![CDATA[]]>			</system-err>
		</testcase>
		<testcase classname="tests.PostTestCase" file="module4\tests.py" line="198" name="test_task6_tag_view_title" time="0.009" timestamp="2020-04-20T11:33:33">
			<failure message="Did you pass the `title` field to the `render` function?" type="AssertionError">
<![CDATA[Traceback (most recent call last):
  File "C:\Users\arkadiusz.trzcinski\Documents\Projects\Django\python-django-models-authentication\module4\tests.py", line 202, in test_task6_tag_view_title
    self.assertTrue(self.tag_view_title_dict_found, msg="Did you pass the `title` field to the `render` function?")
  File "C:\Users\arkadiusz.trzcinski\Documents\Projects\Django\python-django-models-authentication\support\SimplerTestCase.py", line 12, in assertTrue
    self.fail(msg or (str(expr) + "is not True"))
AssertionError: Did you pass the `title` field to the `render` function?
]]>			</failure>
			<system-out>
<![CDATA['Name' object has no attribute 'value'
]]>			</system-out>
			<system-err>
<![CDATA[]]>			</system-err>
		</testcase>
		<testcase classname="tests.PostTestCase" file="module4\tests.py" line="203" name="test_task7_tag_view_find_posts" time="0.005" timestamp="2020-04-20T11:33:33">
			<failure message="Did you set `tag` to `get_object_or_404`'s result?" type="AssertionError">
<![CDATA[Traceback (most recent call last):
  File "C:\Users\arkadiusz.trzcinski\Documents\Projects\Django\python-django-models-authentication\module4\tests.py", line 206, in test_task7_tag_view_find_posts
    self.assertTrue(self.tag_view_get_object_found, msg="Did you set `tag` to `get_object_or_404`'s result?")
  File "C:\Users\arkadiusz.trzcinski\Documents\Projects\Django\python-django-models-authentication\support\SimplerTestCase.py", line 12, in assertTrue
    self.fail(msg or (str(expr) + "is not True"))
AssertionError: Did you set `tag` to `get_object_or_404`'s result?
]]>			</failure>
			<system-out>
<![CDATA['Name' object has no attribute 'value'
]]>			</system-out>
			<system-err>
<![CDATA[]]>			</system-err>
		</testcase>
		<testcase classname="tests.PostTestCase" file="module4\tests.py" line="209" name="test_task8_add_tag_url" time="0.004" timestamp="2020-04-20T11:33:33">
			<failure message="Did you add the tag path to urls.py with the route `'tag/&lt;str:name&gt;'`?" type="AssertionError">
<![CDATA[Traceback (most recent call last):
  File "C:\Users\arkadiusz.trzcinski\Documents\Projects\Django\python-django-models-authentication\module4\tests.py", line 212, in test_task8_add_tag_url
    self.assertTrue(self.tag_posts_route_found, msg="Did you add the tag path to urls.py with the route `'tag/<str:name>'`?")
  File "C:\Users\arkadiusz.trzcinski\Documents\Projects\Django\python-django-models-authentication\support\SimplerTestCase.py", line 12, in assertTrue
    self.fail(msg or (str(expr) + "is not True"))
AssertionError: Did you add the tag path to urls.py with the route `'tag/<str:name>'`?
]]>			</failure>
			<system-out>
<![CDATA[]]>			</system-out>
			<system-err>
<![CDATA[]]>			</system-err>
		</testcase>
		<testcase classname="tests.PostTestCase" file="module4\tests.py" line="236" name="test_task9_url_reverser" time="0.008" timestamp="2020-04-20T11:33:33">
			<failure message="The method `get_absolute_url()` does not exist in the BlogPost model." type="AssertionError">
<![CDATA[Traceback (most recent call last):
  File "C:\Users\arkadiusz.trzcinski\Documents\Projects\Django\python-django-models-authentication\module4\tests.py", line 240, in test_task9_url_reverser
    self.assertTrue(self.get_absolute_url_found, msg="The method `get_absolute_url()` does not exist in the BlogPost model.")
  File "C:\Users\arkadiusz.trzcinski\Documents\Projects\Django\python-django-models-authentication\support\SimplerTestCase.py", line 12, in assertTrue
    self.fail(msg or (str(expr) + "is not True"))
AssertionError: The method `get_absolute_url()` does not exist in the BlogPost model.
]]>			</failure>
			<system-out>
<![CDATA['Name' object has no attribute 's'
]]>			</system-out>
			<system-err>
<![CDATA[]]>			</system-err>
		</testcase>
	</testsuite>
</testsuites>
